Traceback (most recent call last):
  File "/opt/anaconda3/envs/matmek4270/lib/python3.12/site-packages/jupyter_cache/executors/utils.py", line 58, in single_nb_execution
    executenb(
  File "/opt/anaconda3/envs/matmek4270/lib/python3.12/site-packages/nbclient/client.py", line 1314, in execute
    return NotebookClient(nb=nb, resources=resources, km=km, **kwargs).execute()
           ^^^^^^^^^^^^^^^^^^^^^^^^^^^^^^^^^^^^^^^^^^^^^^^^^^^^^^^^^^^^^^^^^^^^^
  File "/opt/anaconda3/envs/matmek4270/lib/python3.12/site-packages/jupyter_core/utils/__init__.py", line 165, in wrapped
    return loop.run_until_complete(inner)
           ^^^^^^^^^^^^^^^^^^^^^^^^^^^^^^
  File "/opt/anaconda3/envs/matmek4270/lib/python3.12/asyncio/base_events.py", line 687, in run_until_complete
    return future.result()
           ^^^^^^^^^^^^^^^
  File "/opt/anaconda3/envs/matmek4270/lib/python3.12/site-packages/nbclient/client.py", line 709, in async_execute
    await self.async_execute_cell(
  File "/opt/anaconda3/envs/matmek4270/lib/python3.12/site-packages/nbclient/client.py", line 1062, in async_execute_cell
    await self._check_raise_for_error(cell, cell_index, exec_reply)
  File "/opt/anaconda3/envs/matmek4270/lib/python3.12/site-packages/nbclient/client.py", line 918, in _check_raise_for_error
    raise CellExecutionError.from_cell_and_msg(cell, exec_reply_content)
nbclient.exceptions.CellExecutionError: An error occurred while executing the following cell:
------------------
w = 2*np.pi 
T, N, I = 3., 35, 1.
dt = T/N 
D2 = sparse.diags([1, -2, 1], np.array([-1, 0, 1]), (N+1, N+1), 'lil')
D2 *= (1/(dt**2))
Id = sparse.eye(N+1, format='lil')
A = (D2 + w**2*Id).to_lil()
b = np.zeros(N+1)
A[0, :3] = 1, 0, 0    # Fix first row
A[-1, -3:] = 0, 0, 1  # Fix last row
b[0] = I
b[-1] = I
u2 = sparse.linalg.spsolve(A, b)
t = np.linspace(0, T, N+1)
plt.plot(t, u2, 'bo', t, I*np.cos(w*t), 'r--')
plt.legend(['Numerical', 'Exact']);
------------------


[0;31m---------------------------------------------------------------------------[0m
[0;31mAttributeError[0m                            Traceback (most recent call last)
Cell [0;32mIn[5], line 7[0m
[1;32m      5[0m D2 [38;5;241m*[39m[38;5;241m=[39m ([38;5;241m1[39m[38;5;241m/[39m(dt[38;5;241m*[39m[38;5;241m*[39m[38;5;241m2[39m))
[1;32m      6[0m Id [38;5;241m=[39m sparse[38;5;241m.[39meye(N[38;5;241m+[39m[38;5;241m1[39m, [38;5;28mformat[39m[38;5;241m=[39m[38;5;124m'[39m[38;5;124mlil[39m[38;5;124m'[39m)
[0;32m----> 7[0m A [38;5;241m=[39m [43m([49m[43mD2[49m[43m [49m[38;5;241;43m+[39;49m[43m [49m[43mw[49m[38;5;241;43m*[39;49m[38;5;241;43m*[39;49m[38;5;241;43m2[39;49m[38;5;241;43m*[39;49m[43mId[49m[43m)[49m[38;5;241;43m.[39;49m[43mto_lil[49m()
[1;32m      8[0m b [38;5;241m=[39m np[38;5;241m.[39mzeros(N[38;5;241m+[39m[38;5;241m1[39m)
[1;32m      9[0m A[[38;5;241m0[39m, :[38;5;241m3[39m] [38;5;241m=[39m [38;5;241m1[39m, [38;5;241m0[39m, [38;5;241m0[39m    [38;5;66;03m# Fix first row[39;00m

[0;31mAttributeError[0m: 'csr_matrix' object has no attribute 'to_lil'

