Traceback (most recent call last):
  File "/Users/mikaelmortensen/opt/anaconda3/envs/bookmatmek4270/lib/python3.9/site-packages/jupyter_cache/executors/utils.py", line 58, in single_nb_execution
    executenb(
  File "/Users/mikaelmortensen/opt/anaconda3/envs/bookmatmek4270/lib/python3.9/site-packages/nbclient/client.py", line 1305, in execute
    return NotebookClient(nb=nb, resources=resources, km=km, **kwargs).execute()
  File "/Users/mikaelmortensen/opt/anaconda3/envs/bookmatmek4270/lib/python3.9/site-packages/jupyter_core/utils/__init__.py", line 166, in wrapped
    return loop.run_until_complete(inner)
  File "/Users/mikaelmortensen/opt/anaconda3/envs/bookmatmek4270/lib/python3.9/asyncio/base_events.py", line 647, in run_until_complete
    return future.result()
  File "/Users/mikaelmortensen/opt/anaconda3/envs/bookmatmek4270/lib/python3.9/site-packages/nbclient/client.py", line 705, in async_execute
    await self.async_execute_cell(
  File "/Users/mikaelmortensen/opt/anaconda3/envs/bookmatmek4270/lib/python3.9/site-packages/nbclient/client.py", line 1058, in async_execute_cell
    await self._check_raise_for_error(cell, cell_index, exec_reply)
  File "/Users/mikaelmortensen/opt/anaconda3/envs/bookmatmek4270/lib/python3.9/site-packages/nbclient/client.py", line 914, in _check_raise_for_error
    raise CellExecutionError.from_cell_and_msg(cell, exec_reply_content)
nbclient.exceptions.CellExecutionError: An error occurred while executing the following cell:
------------------
from lagrange import Lagrangebasis
fig = plt.figure(figsize=(3, 2))
xj = np.array([0, 1])
yj = np.linspace(0, 1, 2)
l0, l1 = Lagrangebasis(xj)
plt.plot(yj, sp.lambdify(x, l0)(yj), 'k',
         yj, sp.lambdify(x, l2)(yj), 'r')
ax = fig.gca()
ax.text(0.95, 0.7, "$\ell_1(x)$", horizontalalignment='center')
ax.text(0.05, 0.7, "$\ell_0(x)$", horizontalalignment='center')
ax.text(0, -0.2, "$x^0$", horizontalalignment='center')
ax.text(1, -0.2, "$x^1$", horizontalalignment='center')
ax.set_xticks([])
ax.set_yticks([0, 1]);
#ax.axis('off');
------------------


Traceback [0;36m(most recent call last)[0m:

[0m  File [1;32m~/opt/anaconda3/envs/bookmatmek4270/lib/python3.9/site-packages/IPython/core/interactiveshell.py:3526[0m in [1;35mrun_code[0m
    exec(code_obj, self.user_global_ns, self.user_ns)[0m

[0m  Cell [1;32mIn[3], line 6[0m
    plt.plot(yj, sp.lambdify(x, l0)(yj), 'k',[0m

[0;36m  File [0;32m~/opt/anaconda3/envs/bookmatmek4270/lib/python3.9/site-packages/sympy/utilities/lambdify.py:903[0;36m in [0;35mlambdify[0;36m
[0;31m    c = compile(funcstr, filename, 'exec')[0;36m

[0;36m  File [0;32m<lambdifygenerated-1>:1[0;36m[0m
[0;31m    def _lambdifygenerated(0.8090169943749475, 1.0):[0m
[0m                           ^[0m
[0;31mSyntaxError[0m[0;31m:[0m invalid syntax


